Traceback (most recent call last):
  File "C:\Users\sayala\AppData\Roaming\Python\Python311\site-packages\jupyter_cache\executors\utils.py", line 58, in single_nb_execution
    executenb(
  File "C:\ProgramData\Anaconda3\Lib\site-packages\nbclient\client.py", line 1204, in execute
    return NotebookClient(nb=nb, resources=resources, km=km, **kwargs).execute()
           ^^^^^^^^^^^^^^^^^^^^^^^^^^^^^^^^^^^^^^^^^^^^^^^^^^^^^^^^^^^^^^^^^^^^^
  File "C:\ProgramData\Anaconda3\Lib\site-packages\nbclient\util.py", line 84, in wrapped
    return just_run(coro(*args, **kwargs))
           ^^^^^^^^^^^^^^^^^^^^^^^^^^^^^^^
  File "C:\ProgramData\Anaconda3\Lib\site-packages\nbclient\util.py", line 62, in just_run
    return loop.run_until_complete(coro)
           ^^^^^^^^^^^^^^^^^^^^^^^^^^^^^
  File "C:\ProgramData\Anaconda3\Lib\asyncio\base_events.py", line 653, in run_until_complete
    return future.result()
           ^^^^^^^^^^^^^^^
  File "C:\ProgramData\Anaconda3\Lib\site-packages\nbclient\client.py", line 663, in async_execute
    await self.async_execute_cell(
  File "C:\ProgramData\Anaconda3\Lib\site-packages\nbclient\client.py", line 965, in async_execute_cell
    await self._check_raise_for_error(cell, cell_index, exec_reply)
  File "C:\ProgramData\Anaconda3\Lib\site-packages\nbclient\client.py", line 862, in _check_raise_for_error
    raise CellExecutionError.from_cell_and_msg(cell, exec_reply_content)
nbclient.exceptions.CellExecutionError: An error occurred while executing the following cell:
------------------
import pvanalytics
pvanalytics.__version__
import pvlib
import matplotlib
import matplotlib.pyplot as plt
import pandas as pd
import pathlib  # this might not be needed as working on same directory as data here?
from datetime import timedelta
import rdtools
------------------

[1;31m---------------------------------------------------------------------------[0m
[1;31mAttributeError[0m                            Traceback (most recent call last)
Cell [1;32mIn[2], line 2[0m
[0;32m      1[0m [38;5;28;01mimport[39;00m [38;5;21;01mpvanalytics[39;00m
[1;32m----> 2[0m pvanalytics[38;5;241m.[39m__version__
[0;32m      3[0m [38;5;28;01mimport[39;00m [38;5;21;01mpvlib[39;00m
[0;32m      4[0m [38;5;28;01mimport[39;00m [38;5;21;01mmatplotlib[39;00m

[1;31mAttributeError[0m: module 'pvanalytics' has no attribute '__version__'
AttributeError: module 'pvanalytics' has no attribute '__version__'

